<?xml version='1.0'?>
<sdf version='1.6'>
  <model name='Vaccum_Robot'>
  	<pose>0 0 0.070010 0 -0 0</pose>
  
    <link name='dd_body'>
      <pose frame=''>-0.017604 0.105911 0.065472 0 -0 0</pose>
      <inertial>
        <mass>10</mass>
        <inertia>
          <ixx>0.0373069</ixx>
          <iyy>0.0685157</iyy>
          <izz>0.0389621</izz>
          <ixy>0</ixy>
          <ixz>0</ixz>
          <iyz>0</iyz>
        </inertia>
      </inertial>
      <collision name='collision'>
        <geometry>
          <cylinder>
            <radius>0.3092</radius>
            <length>0.204463</length>
          </cylinder>
        </geometry>
      </collision>
      <visual name='visual'>
        <geometry>
          <mesh>
            <uri>model://ddrobot/meshes/1.dae</uri>
            <scale>0.002 0.002 0.002</scale>
          </mesh>
        </geometry>
      </visual>
    </link>

    <link name='caster_wheel'>
      <pose frame=''>-0.01847 -0.125539 -0.057024 3.14159 1.55042 3.14159</pose>  
      <inertial>
        <mass>0.699997</mass>
        <inertia>
          <ixx>0.0426374</ixx>
          <ixy>0</ixy>
          <ixz>0</ixz>
          <iyy>0.0426374</iyy>
          <iyz>0</iyz>
          <izz>0.0364703</izz>
        </inertia>
        <pose frame=''>0 0 0 0 -0 0</pose>
      </inertial>
      <gravity>1</gravity>
      <self_collide>0</self_collide>
      <kinematic>0</kinematic>
      <visual name='visual'>
        <pose frame=''>0 0 0 0 -0 0</pose>
        <geometry>
          <cylinder>
            <radius>0.0215192</radius>
            <length>0.0304785</length>
          </cylinder>
        </geometry>
        <material>
          <lighting>1</lighting>
          <script>
            <uri>file://media/materials/scripts/gazebo.material</uri>
            <name>Gazebo/Grey</name>
          </script>
          <ambient>0.3 0.3 0.3 1</ambient>
          <diffuse>0.7 0.7 0.7 1</diffuse>
          <specular>0.01 0.01 0.01 1</specular>
          <emissive>0 0 0 1</emissive>
          <shader type='vertex'>
            <normal_map>__default__</normal_map>
          </shader>
        </material>
        <cast_shadows>1</cast_shadows>
        <transparency>0</transparency>
      </visual>
      <collision name='collision'>
        <laser_retro>0</laser_retro>
        <max_contacts>10</max_contacts>
        <pose frame=''>0 0 0 0 -0 0</pose>
        <geometry>
          <cylinder>
            <radius>0.0215192</radius>
            <length>0.0304785</length>
          </cylinder>
        </geometry>
        <surface>
          <friction>
            <ode>
              <mu>1</mu>
              <mu2>1</mu2>
              <fdir1>0 0 0</fdir1>
              <slip1>0</slip1>
              <slip2>0</slip2>
            </ode>
            <torsional>
              <coefficient>1</coefficient>
              <patch_radius>0</patch_radius>
              <surface_radius>0</surface_radius>
              <use_patch_radius>1</use_patch_radius>
              <ode>
                <slip>0</slip>
              </ode>
            </torsional>
          </friction>
          <bounce>
            <restitution_coefficient>0</restitution_coefficient>
            <threshold>1e+06</threshold>
          </bounce>
          <contact>
            <collide_without_contact>0</collide_without_contact>
            <collide_without_contact_bitmask>1</collide_without_contact_bitmask>
            <collide_bitmask>1</collide_bitmask>
            <ode>
              <soft_cfm>0</soft_cfm>
              <soft_erp>0.2</soft_erp>
              <kp>1e+13</kp>
              <kd>1</kd>
              <max_vel>0.01</max_vel>
              <min_depth>0</min_depth>
            </ode>
            <bullet>
              <split_impulse>1</split_impulse>
              <split_impulse_penetration_threshold>-0.01</split_impulse_penetration_threshold>
              <soft_cfm>0</soft_cfm>
              <soft_erp>0.2</soft_erp>
              <kp>1e+13</kp>
              <kd>1</kd>
            </bullet>
          </contact>
        </surface>
      </collision>
    </link> 

    <link name='right_wheel'>
      <pose frame=''>-0.269883 0.118093 0.000571 3.11153 -1.56428 -3.14159</pose>
      <!--pose frame=''>4e-06 -4e-06 0 3.11153 -1.56428 -3.14159</pose-->
      <inertial>
        <mass>0.25</mass>
        <inertia>
          <ixx>0.145833</ixx>
          <ixy>0</ixy>
          <ixz>0</ixz>
          <iyy>0.145833</iyy>
          <iyz>0</iyz>
          <izz>0.125</izz>
        </inertia>
        <pose frame=''>0 0 0 0 -0 0</pose>
      </inertial>
      <gravity>1</gravity>
      <self_collide>0</self_collide>
      <kinematic>0</kinematic>
      <visual name='ModelPreview_0::link_0::visual_1'>
        <pose frame=''>0 0 0 0 -0 0</pose>
        <geometry>
          <cylinder>
            <radius>0.0753</radius>
            <length>0.08</length>
          </cylinder>
        </geometry>
        <material>
          <lighting>1</lighting>
          <script>
            <uri>file://media/materials/scripts/gazebo.material</uri>
            <name>Gazebo/Grey</name>
          </script>
          <ambient>0.3 0.3 0.3 1</ambient>
          <diffuse>0.7 0.7 0.7 1</diffuse>
          <specular>0.01 0.01 0.01 1</specular>
          <emissive>0 0 0 1</emissive>
          <shader type='vertex'>
            <normal_map>__default__</normal_map>
          </shader>
        </material>
        <cast_shadows>1</cast_shadows>
        <transparency>0</transparency>
      </visual>
      <visual name='visual'>
        <pose frame=''>0 0 0 0 -0 0</pose>
        <geometry>
          <cylinder>
            <radius>0.0753</radius>
            <length>0.08</length>
          </cylinder>
        </geometry>
        <material>
          <lighting>1</lighting>
          <script>
            <uri>file://media/materials/scripts/gazebo.material</uri>
            <name>Gazebo/Grey</name>
          </script>
          <ambient>0.3 0.3 0.3 1</ambient>
          <diffuse>0.7 0.7 0.7 1</diffuse>
          <specular>0.01 0.01 0.01 1</specular>
          <emissive>0 0 0 1</emissive>
          <shader type='vertex'>
            <normal_map>__default__</normal_map>
          </shader>
        </material>
        <cast_shadows>1</cast_shadows>
        <transparency>0</transparency>
      </visual>
      <collision name='collision'>
        <laser_retro>0</laser_retro>
        <max_contacts>10</max_contacts>
        <pose frame=''>0 0 0 0 -0 0</pose>
        <geometry>
          <cylinder>
            <radius>0.0753</radius>
            <length>0.08</length>
          </cylinder>
        </geometry>
        <surface>
          <friction>
            <ode>
              <mu>1</mu>
              <mu2>1</mu2>
              <fdir1>0 0 0</fdir1>
              <slip1>0</slip1>
              <slip2>0</slip2>
            </ode>
            <torsional>
              <coefficient>1</coefficient>
              <patch_radius>0</patch_radius>
              <surface_radius>0</surface_radius>
              <use_patch_radius>1</use_patch_radius>
              <ode>
                <slip>0</slip>
              </ode>
            </torsional>
          </friction>
          <bounce>
            <restitution_coefficient>0</restitution_coefficient>
            <threshold>1e+06</threshold>
          </bounce>
          <contact>
            <collide_without_contact>0</collide_without_contact>
            <collide_without_contact_bitmask>1</collide_without_contact_bitmask>
            <collide_bitmask>1</collide_bitmask>
            <ode>
              <soft_cfm>0</soft_cfm>
              <soft_erp>0.2</soft_erp>
              <kp>1e+13</kp>
              <kd>1</kd>
              <max_vel>0.01</max_vel>
              <min_depth>0</min_depth>
            </ode>
            <bullet>
              <split_impulse>1</split_impulse>
              <split_impulse_penetration_threshold>-0.01</split_impulse_penetration_threshold>
              <soft_cfm>0</soft_cfm>
              <soft_erp>0.2</soft_erp>
              <kp>1e+13</kp>
              <kd>1</kd>
            </bullet>
          </contact>
        </surface>
      </collision>
    </link>
    
    <link name='left_wheel'>
      <pose frame=''>0.232285 0.118093 0.000571 3.11153 -1.56428 -3.14159</pose>
      <!--pose frame=''>4e-06 -4e-06 0 3.11153 -1.56428 -3.14159</pose-->
      <inertial>
        <mass>0.25</mass>
        <inertia>
          <ixx>0.145833</ixx>
          <ixy>0</ixy>
          <ixz>0</ixz>
          <iyy>0.145833</iyy>
          <iyz>0</iyz>
          <izz>0.125</izz>
        </inertia>
        <pose frame=''>0 0 0 0 -0 0</pose>
      </inertial>
      <gravity>1</gravity>
      <self_collide>0</self_collide>
      <kinematic>0</kinematic>
      <visual name='ModelPreview_0::link_0::visual_1'>
        <pose frame=''>0 0 0 0 -0 0</pose>
        <geometry>
          <cylinder>
            <radius>0.0753</radius>
            <length>0.08</length>
          </cylinder>
        </geometry>
        <material>
          <lighting>1</lighting>
          <script>
            <uri>file://media/materials/scripts/gazebo.material</uri>
            <name>Gazebo/Grey</name>
          </script>
          <ambient>0.3 0.3 0.3 1</ambient>
          <diffuse>0.7 0.7 0.7 1</diffuse>
          <specular>0.01 0.01 0.01 1</specular>
          <emissive>0 0 0 1</emissive>
          <shader type='vertex'>
            <normal_map>__default__</normal_map>
          </shader>
        </material>
        <cast_shadows>1</cast_shadows>
        <transparency>0</transparency>
      </visual>
      <visual name='visual'>
        <pose frame=''>0 0 0 0 -0 0</pose>
        <geometry>
          <cylinder>
            <radius>0.0753</radius>
            <length>0.08</length>
          </cylinder>
        </geometry>
        <material>
          <lighting>1</lighting>
          <script>
            <uri>file://media/materials/scripts/gazebo.material</uri>
            <name>Gazebo/Grey</name>
          </script>
          <ambient>0.3 0.3 0.3 1</ambient>
          <diffuse>0.7 0.7 0.7 1</diffuse>
          <specular>0.01 0.01 0.01 1</specular>
          <emissive>0 0 0 1</emissive>
          <shader type='vertex'>
            <normal_map>__default__</normal_map>
          </shader>
        </material>
        <cast_shadows>1</cast_shadows>
        <transparency>0</transparency>
      </visual>
      <collision name='collision'>
        <laser_retro>0</laser_retro>
        <max_contacts>10</max_contacts>
        <pose frame=''>0 0 0 0 -0 0</pose>
        <geometry>
          <cylinder>
            <radius>0.0753</radius>
            <length>0.08</length>
          </cylinder>
        </geometry>
        <surface>
          <friction>
            <ode>
              <mu>1</mu>
              <mu2>1</mu2>
              <fdir1>0 0 0</fdir1>
              <slip1>0</slip1>
              <slip2>0</slip2>
            </ode>
            <torsional>
              <coefficient>1</coefficient>
              <patch_radius>0</patch_radius>
              <surface_radius>0</surface_radius>
              <use_patch_radius>1</use_patch_radius>
              <ode>
                <slip>0</slip>
              </ode>
            </torsional>
          </friction>
          <bounce>
            <restitution_coefficient>0</restitution_coefficient>
            <threshold>1e+06</threshold>
          </bounce>
          <contact>
            <collide_without_contact>0</collide_without_contact>
            <collide_without_contact_bitmask>1</collide_without_contact_bitmask>
            <collide_bitmask>1</collide_bitmask>
            <ode>
              <soft_cfm>0</soft_cfm>
              <soft_erp>0.2</soft_erp>
              <kp>1e+13</kp>
              <kd>1</kd>
              <max_vel>0.01</max_vel>
              <min_depth>0</min_depth>
            </ode>
            <bullet>
              <split_impulse>1</split_impulse>
              <split_impulse_penetration_threshold>-0.01</split_impulse_penetration_threshold>
              <soft_cfm>0</soft_cfm>
              <soft_erp>0.2</soft_erp>
              <kp>1e+13</kp>
              <kd>1</kd>
            </bullet>
          </contact>
        </surface>
      </collision>
    </link>
    
    
  	<joint name='base_link_JOINT_0' type='revolute'>
	    <parent>dd_body</parent>
	    <child>right_wheel</child>
	    <pose frame=''>0 0 0 0 -0 0</pose>
	    <axis>
	      <xyz>0 0 -1</xyz>
	      <use_parent_model_frame>0</use_parent_model_frame>
	      <limit>
	        <lower>-1.79769e+308</lower>
	        <upper>1.79769e+308</upper>
	        <effort>-1</effort>
	        <velocity>-1</velocity>
	      </limit>
	      <dynamics>
	        <spring_reference>0</spring_reference>
	        <spring_stiffness>0</spring_stiffness>
	        <damping>0</damping>
	      </dynamics>
	    </axis>
	    <physics>
	      <ode>
	        <limit>
	          <cfm>0</cfm>
	          <erp>0.2</erp>
	        </limit>
	        <suspension>
	          <cfm>0</cfm>
	          <erp>0.2</erp>
	        </suspension>
	      </ode>
	    </physics>
	</joint>
  	<joint name='base_link_JOINT_1' type='revolute'>
	    <parent>dd_body</parent>
	    <child>left_wheel</child>
	    <pose frame=''>0 0 0 0 -0 0</pose>
	    <axis>
	      <xyz>0 0 -1</xyz>
	      <use_parent_model_frame>0</use_parent_model_frame>
	      <limit>
	        <lower>-1.79769e+308</lower>
	        <upper>1.79769e+308</upper>
	        <effort>-1</effort>
	        <velocity>-1</velocity>
	      </limit>
	      <dynamics>
	        <spring_reference>0</spring_reference>
	        <spring_stiffness>0</spring_stiffness>
	        <damping>0</damping>
	      </dynamics>
	    </axis>
	    <physics>
	      <ode>
	        <limit>
	          <cfm>0</cfm>
	          <erp>0.2</erp>
	        </limit>
	        <suspension>
	          <cfm>0</cfm>
	          <erp>0.2</erp>
	        </suspension>
	      </ode>
	    </physics>
  	</joint>
  	<joint name='base_link_JOINT_2' type='revolute'>
	    <parent>dd_body</parent>
	    <child>caster_wheel</child>
	    <pose frame=''>0 0 0 0 -0 0</pose>
	    <axis>
	      <xyz>0 0 -1</xyz>
	      <use_parent_model_frame>0</use_parent_model_frame>
	      <limit>
	        <lower>-1.79769e+308</lower>
	        <upper>1.79769e+308</upper>
	        <effort>-1</effort>
	        <velocity>-1</velocity>
	      </limit>
	      <dynamics>
	        <spring_reference>0</spring_reference>
	        <spring_stiffness>0</spring_stiffness>
	        <damping>0</damping>
	      </dynamics>
	    </axis>
	    <physics>
	      <ode>
	        <limit>
	          <cfm>0</cfm>
	          <erp>0.2</erp>
	        </limit>
	        <suspension>
	          <cfm>0</cfm>
	          <erp>0.2</erp>
	        </suspension>
	      </ode>
	    </physics>
  	</joint>
  
  	<plugin name='differential_drive_controller' filename='libgazebo_ros_diff_drive.so'>
	    <legacyMode>flase</legacyMode>
	    <alwaysOn>true</alwaysOn>
	    <updateRate>20</updateRate>
	    <leftJoint>base_link_JOINT_0</leftJoint>
	    <rightJoint>base_link_JOINT_1</rightJoint>
	    <wheelSeparation>0.47</wheelSeparation>
	    <wheelDiameter>0.16</wheelDiameter>
	    <torque>10</torque>
	    <commandTopic>/cmd_vel</commandTopic>
	    <odometryTopic>/odom</odometryTopic>
	    <odometryFrame>/odom</odometryFrame>
	    <robotBaseFrame>/dd_body</robotBaseFrame>
	</plugin>
  <plugin name="gazebo_ros_control" filename="libgazebo_ros_control.so">
    <robotNamespace>/VaccumRobot</robotNamespace>
  </plugin>

  <!--pose frame=''>0.008872 -0.014092 -0.131537 0 -0 0</pose-->

	<link name='hokuyo'>
	   	<pose frame=''>-0.008872 0.014092 0.179997 0 -0 -1.57</pose>
	    <gravity>0</gravity>
	    <inertial>
	      <mass>0.1</mass>
	    </inertial>
	    <visual name='visual'>
	      <geometry>
	        <mesh>
	          <uri>model://hokuyo/meshes/hokuyo.dae</uri>
	        </mesh>
	      </geometry>
	    </visual>
	    <sensor name='hokuyo' type='ray'>
	      <pose frame=''>0.01 0 0.03 0 -0 0</pose>
	      <ray>
	        <scan>
	          <horizontal>
	            <samples>640</samples>
	            <resolution>1</resolution>
	            <min_angle>-2.26889</min_angle>
	            <max_angle>2.2689</max_angle>
	          </horizontal>
	        </scan>
	        <range>
	          <min>0.08</min>
	          <max>10</max>
	          <resolution>0.01</resolution>
	        </range>
	        <noise>
	          <type>gaussian</type>
	          <mean>0</mean>
	          <stddev>0</stddev>
	        </noise>
	      </ray>
	      <plugin name='laser_plugin' filename='libgazebo_ros_laser.so'>
	          <topicName>/scan</topicName>
	          <frameName>hokuyo</frameName>
	      </plugin>
	      <always_on>1</always_on>
	      <update_rate>30</update_rate>
	      <visualize>0</visualize>
	    </sensor>
	</link>
    <joint name='base_link_JOINT_3' type='fixed'>
      <parent>dd_body</parent>
      <child>hokuyo</child>
      <pose frame=''>0 0 0 0 -0 0</pose>
      <physics>
        <ode>
          <limit>
            <cfm>0</cfm>
            <erp>0.2</erp>
          </limit>
          <suspension>
            <cfm>0</cfm>
            <erp>0.2</erp>
          </suspension>
        </ode>
      </physics>
    </joint>
    <static>0</static>
    <allow_auto_disable>1</allow_auto_disable>
  </model>
</sdf>
